<?xml version="1.0" ?>
<sdf version="1.6">
	<model name="musc_shoulder">
		<link name="arm">
			<self_collide>false</self_collide>
			<pose frame="">-0.21847213651153902 0.024365474584233385 0.17377421917548969 0.0 -0.0 0.0</pose>
			<inertial>
				<pose frame="">0.0 0.0 0.0 0 0 0</pose>
				<mass>1.3900711467671745</mass>
				<inertia>
					<ixx>0.05165470764810388</ixx>
					<ixy>0.007395005001894429</ixy>
					<ixz>0.05294857060727835</ixz>
					<iyy>0.11721077113089157</iyy>
					<iyz>-0.0058812250172963505</iyz>
					<izz>0.0682664756117262</izz>
				</inertia>
			</inertial>
			<collision name="arm_collision">
				<geometry>
					<mesh>
						<uri>model://musc_shoulder/meshes/CAD/arm.stl</uri>
						<scale>0.001 0.001 0.001</scale>
					</mesh>
				</geometry>
			</collision>
			<visual name="arm_visual">
				<geometry>
					<mesh>
						<uri>model://musc_shoulder/meshes/CAD/arm.stl</uri>
						<scale>0.001 0.001 0.001</scale>
					</mesh>
				</geometry>
			</visual>
		</link>
		<link name="base">
			<self_collide>false</self_collide>
			<pose frame="">-0.07334528980417672 0.025033465691658884 0.25408470509439013 0.0 -0.0 0.0</pose>
			<inertial>
				<pose frame="">0.0 0.0 0.0 0 0 0</pose>
				<mass>5.129823793617418</mass>
				<inertia>
					<ixx>0.3924898054873209</ixx>
					<ixy>0.009815079439375258</ixy>
					<ixz>0.10252824580446568</ixz>
					<iyy>0.41722624828278</iyy>
					<iyz>-0.03302147764825088</iyz>
					<izz>0.06630957472950233</izz>
				</inertia>
			</inertial>
			<collision name="base_collision">
				<geometry>
					<mesh>
						<uri>model://musc_shoulder/meshes/CAD/base.stl</uri>
						<scale>0.001 0.001 0.001</scale>
					</mesh>
				</geometry>
			</collision>
			<visual name="base_visual">
				<geometry>
					<mesh>
						<uri>model://musc_shoulder/meshes/CAD/base.stl</uri>
						<scale>0.001 0.001 0.001</scale>
					</mesh>
				</geometry>
			</visual>
		</link>
		<link name="shoulder_link1">
			<self_collide>false</self_collide>
			<pose frame="">-0.20427966495257033 0.029062023483753686 0.37683608816424163 0.0 -0.0 0.0</pose>
			<inertial>
				<pose frame="">0.0 0.0 0.0 0 0 0</pose>
				<mass>3.839261942680571e-06</mass>
				<inertia>
					<ixx>5.48659016768844e-07</ixx>
					<ixy>2.2809314376729742e-08</ixy>
					<ixz>2.9554619174033445e-07</ixz>
					<iyy>7.05611674891562e-07</iyy>
					<iyz>-4.204613497327697e-08</iyz>
					<izz>1.6356395688392827e-07</izz>
				</inertia>
			</inertial>
			<collision name="shoulder_link1_collision">
				<geometry>
					<mesh>
						<uri>model://musc_shoulder/meshes/CAD/shoulder_link1.stl</uri>
						<scale>0.001 0.001 0.001</scale>
					</mesh>
				</geometry>
			</collision>
			<visual name="shoulder_link1_visual">
				<geometry>
					<mesh>
						<uri>model://musc_shoulder/meshes/CAD/shoulder_link1.stl</uri>
						<scale>0.001 0.001 0.001</scale>
					</mesh>
				</geometry>
			</visual>
		</link>
		<link name="shoulder_link2">
			<self_collide>false</self_collide>
			<pose frame="">-0.21278835033779747 0.01906219044173891 0.37607426618071155 0.0 -0.0 0.0</pose>
			<inertial>
				<pose frame="">0.0 0.0 0.0 0 0 0</pose>
				<mass>4.639261942680568e-06</mass>
				<inertia>
					<ixx>6.580421799820622e-07</ixx>
					<ixy>1.8829176836912352e-08</ixy>
					<ixz>3.712758817844876e-07</ixz>
					<iyy>8.664972320005396e-07</iyy>
					<iyz>-3.3255090176524245e-08</iyz>
					<izz>2.119300388119357e-07</izz>
				</inertia>
			</inertial>
			<collision name="shoulder_link2_collision">
				<geometry>
					<mesh>
						<uri>model://musc_shoulder/meshes/CAD/shoulder_link2.stl</uri>
						<scale>0.001 0.001 0.001</scale>
					</mesh>
				</geometry>
			</collision>
			<visual name="shoulder_link2_visual">
				<geometry>
					<mesh>
						<uri>model://musc_shoulder/meshes/CAD/shoulder_link2.stl</uri>
						<scale>0.001 0.001 0.001</scale>
					</mesh>
				</geometry>
			</visual>
		</link>
		<joint name="shoulder_axis0" type="revolute">
			<parent>base</parent>
			<child>shoulder_link1</child>
			<pose frame="">-0.005523392445821323 -0.004667079157304231 0.0 0 0 0</pose>
			<axis>
				<xyz>-1.8474149676157256e-47 -1.0 4.996003610813204e-16</xyz>
				<limit>
					<lower>0.0</lower>
					<upper>1.5707963267948966</upper>
				</limit>
				<use_parent_model_frame>0</use_parent_model_frame>
			</axis>
		</joint>
		<joint name="shoulder_axis1" type="revolute">
			<parent>shoulder_link1</parent>
			<child>shoulder_link2</child>
			<pose frame="">0.01712742856313682 0.0053327538847105505 0.0007618219835300266 0 0 0</pose>
			<axis>
				<xyz>1.0 0.0 0.0</xyz>
				<limit>
					<lower>-1.5707963267948966</lower>
					<upper>1.5707963267948966</upper>
				</limit>
				<use_parent_model_frame>0</use_parent_model_frame>
			</axis>
		</joint>
		<joint name="shoulder_axis2" type="revolute">
			<parent>shoulder_link2</parent>
			<child>arm</child>
			<pose frame="">0.008669079113147404 2.9469742216075013e-05 0.20306186898875186 0 0 0</pose>
			<axis>
				<xyz>0.0 6.2803698347351125e-16 1.0</xyz>
				<limit>
					<lower>-1.2217304763960306</lower>
					<upper>1.2217304763960306</upper>
				</limit>
				<use_parent_model_frame>0</use_parent_model_frame>
			</axis>
		</joint>
		<plugin filename="libcardsflow_gazebo_plugin.so" name="cardsflow_gazebo_plugin"/>
	</model>
</sdf>
